 * Restarting with stat
 * Debugger is active!
 * Debugger PIN: 138-769-367
(8357) wsgi starting up on http://0.0.0.0:5200
(8357) accepted ('127.0.0.1', 51498)
127.0.0.1 - - [12/Dec/2017 22:03:21] "GET / HTTP/1.1" 200 5283 0.004259
127.0.0.1 - - [12/Dec/2017 22:03:21] "GET /lib/jquery-ui/themes/smoothness/jquery-ui.css HTTP/1.1" 200 36863 0.003123
(8357) accepted ('127.0.0.1', 51499)
127.0.0.1 - - [12/Dec/2017 22:03:21] "GET /pages/mainPage/css/app.css HTTP/1.1" 200 52351 0.004071
127.0.0.1 - - [12/Dec/2017 22:03:21] "GET /lib/jquery/dist/jquery.js HTTP/1.1" 200 267522 0.005218
127.0.0.1 - - [12/Dec/2017 22:03:21] "GET /lib/angular-ui-date/dist/date.js HTTP/1.1" 200 10115 0.002255
127.0.0.1 - - [12/Dec/2017 22:03:21] "GET /lib/jquery-ui/jquery-ui.js HTTP/1.1" 200 521042 0.009302
(8357) accepted ('127.0.0.1', 51502)
(8357) accepted ('127.0.0.1', 51503)
(8357) accepted ('127.0.0.1', 51504)
(8357) accepted ('127.0.0.1', 51505)
127.0.0.1 - - [12/Dec/2017 22:03:21] "GET /lib/angular-animate/angular-animate.js HTTP/1.1" 200 151157 0.003506
127.0.0.1 - - [12/Dec/2017 22:03:21] "GET /lib/lodash/dist/lodash.js HTTP/1.1" 200 527458 0.005098
127.0.0.1 - - [12/Dec/2017 22:03:21] "GET /lib/angular-resource/angular-resource.js HTTP/1.1" 200 35641 0.002683
127.0.0.1 - - [12/Dec/2017 22:03:21] "GET /lib/angular-route/angular-route.js HTTP/1.1" 200 39273 0.023506
127.0.0.1 - - [12/Dec/2017 22:03:21] "GET /pages/mainPage/js/app.js HTTP/1.1" 200 9193 0.001746
127.0.0.1 - - [12/Dec/2017 22:03:21] "GET /lib/angular/angular.js HTTP/1.1" 200 1221514 0.046377
127.0.0.1 - - [12/Dec/2017 22:03:22] "GET /favicon.ico HTTP/1.1" 404 366 0.001558
127.0.0.1 - - [12/Dec/2017 22:03:22] "GET /favicon.ico HTTP/1.1" 404 366 0.000941
127.0.0.1 - - [12/Dec/2017 22:03:22] "GET /socket.io/?EIO=3&transport=polling&t=M1DqvpP HTTP/1.1" 200 381 0.000597
127.0.0.1 - - [12/Dec/2017 22:03:22] "GET /pages/mainPage/views/blockchain.html HTTP/1.1" 200 1948 0.001662
127.0.0.1 - - [12/Dec/2017 22:03:22] "POST /socket.io/?EIO=3&transport=polling&t=M1Dqvqm&sid=9dd38cb89b184394b26bf585c6630e57 HTTP/1.1" 200 199 0.001382
127.0.0.1 - - [12/Dec/2017 22:03:22] "GET /socket.io/?EIO=3&transport=polling&t=M1Dqvqp&sid=9dd38cb89b184394b26bf585c6630e57 HTTP/1.1" 200 270 0.000273
(8357) accepted ('127.0.0.1', 51508)
message handler error
Traceback (most recent call last):
  File "/usr/local/lib/python3.6/site-packages/urllib3/connection.py", line 141, in _new_conn
    (self.host, self.port), self.timeout, **extra_kw)
  File "/usr/local/lib/python3.6/site-packages/urllib3/util/connection.py", line 83, in create_connection
    raise err
  File "/usr/local/lib/python3.6/site-packages/urllib3/util/connection.py", line 73, in create_connection
    sock.connect(sa)
ConnectionRefusedError: [Errno 61] Connection refused

During handling of the above exception, another exception occurred:

Traceback (most recent call last):
  File "/usr/local/lib/python3.6/site-packages/urllib3/connectionpool.py", line 601, in urlopen
    chunked=chunked)
  File "/usr/local/lib/python3.6/site-packages/urllib3/connectionpool.py", line 357, in _make_request
    conn.request(method, url, **httplib_request_kw)
  File "/usr/local/Cellar/python3/3.6.2/Frameworks/Python.framework/Versions/3.6/lib/python3.6/http/client.py", line 1239, in request
    self._send_request(method, url, body, headers, encode_chunked)
  File "/usr/local/Cellar/python3/3.6.2/Frameworks/Python.framework/Versions/3.6/lib/python3.6/http/client.py", line 1285, in _send_request
    self.endheaders(body, encode_chunked=encode_chunked)
  File "/usr/local/Cellar/python3/3.6.2/Frameworks/Python.framework/Versions/3.6/lib/python3.6/http/client.py", line 1234, in endheaders
    self._send_output(message_body, encode_chunked=encode_chunked)
  File "/usr/local/Cellar/python3/3.6.2/Frameworks/Python.framework/Versions/3.6/lib/python3.6/http/client.py", line 1026, in _send_output
    self.send(msg)
  File "/usr/local/Cellar/python3/3.6.2/Frameworks/Python.framework/Versions/3.6/lib/python3.6/http/client.py", line 964, in send
    self.connect()
  File "/usr/local/lib/python3.6/site-packages/urllib3/connection.py", line 166, in connect
    conn = self._new_conn()
  File "/usr/local/lib/python3.6/site-packages/urllib3/connection.py", line 150, in _new_conn
    self, "Failed to establish a new connection: %s" % e)
urllib3.exceptions.NewConnectionError: <urllib3.connection.HTTPConnection object at 0x104992b00>: Failed to establish a new connection: [Errno 61] Connection refused

During handling of the above exception, another exception occurred:

Traceback (most recent call last):
  File "/usr/local/lib/python3.6/site-packages/requests/adapters.py", line 440, in send
    timeout=timeout
  File "/usr/local/lib/python3.6/site-packages/urllib3/connectionpool.py", line 639, in urlopen
    _stacktrace=sys.exc_info()[2])
  File "/usr/local/lib/python3.6/site-packages/urllib3/util/retry.py", line 388, in increment
    raise MaxRetryError(_pool, url, error or ResponseError(cause))
urllib3.exceptions.MaxRetryError: HTTPConnectionPool(host='localhost', port=4200): Max retries exceeded with url: /get-peer-addresses (Caused by NewConnectionError('<urllib3.connection.HTTPConnection object at 0x104992b00>: Failed to establish a new connection: [Errno 61] Connection refused',))

During handling of the above exception, another exception occurred:

Traceback (most recent call last):
  File "/usr/local/lib/python3.6/site-packages/engineio/server.py", line 405, in _trigger_event
    return self.handlers[event](*args)
  File "/usr/local/lib/python3.6/site-packages/socketio/server.py", line 522, in _handle_eio_message
    self._handle_event(sid, pkt.namespace, pkt.id, pkt.data)
  File "/usr/local/lib/python3.6/site-packages/socketio/server.py", line 458, in _handle_event
    self._handle_event_internal(self, sid, data, namespace, id)
  File "/usr/local/lib/python3.6/site-packages/socketio/server.py", line 461, in _handle_event_internal
    r = server._trigger_event(data[0], namespace, sid, *data[1:])
  File "/usr/local/lib/python3.6/site-packages/socketio/server.py", line 490, in _trigger_event
    return self.handlers[namespace][event](*args)
  File "/usr/local/lib/python3.6/site-packages/flask_socketio/__init__.py", line 243, in _handler
    *args)
  File "/usr/local/lib/python3.6/site-packages/flask_socketio/__init__.py", line 626, in _handle_event
    ret = handler(*args)
  File "/Users/siddharthsudheer/repos/computer-science/alysida/webapp/app/routes/index.py", line 52, in get_peers
    resp = requests.get(endpoint)
  File "/usr/local/lib/python3.6/site-packages/requests/api.py", line 72, in get
    return request('get', url, params=params, **kwargs)
  File "/usr/local/lib/python3.6/site-packages/requests/api.py", line 58, in request
    return session.request(method=method, url=url, **kwargs)
  File "/usr/local/lib/python3.6/site-packages/requests/sessions.py", line 508, in request
    resp = self.send(prep, **send_kwargs)
  File "/usr/local/lib/python3.6/site-packages/requests/sessions.py", line 618, in send
    r = adapter.send(request, **kwargs)
  File "/usr/local/lib/python3.6/site-packages/requests/adapters.py", line 508, in send
    raise ConnectionError(e, request=request)
requests.exceptions.ConnectionError: HTTPConnectionPool(host='localhost', port=4200): Max retries exceeded with url: /get-peer-addresses (Caused by NewConnectionError('<urllib3.connection.HTTPConnection object at 0x104992b00>: Failed to establish a new connection: [Errno 61] Connection refused',))
127.0.0.1 - - [12/Dec/2017 22:03:22] "POST /socket.io/?EIO=3&transport=polling&t=M1Dqvrd&sid=9dd38cb89b184394b26bf585c6630e57 HTTP/1.1" 200 199 0.041780
127.0.0.1 - - [12/Dec/2017 22:03:22] "GET /socket.io/?EIO=3&transport=polling&t=M1Dqvrd.0&sid=9dd38cb89b184394b26bf585c6630e57 HTTP/1.1" 200 215 0.000596
message handler error
Traceback (most recent call last):
  File "/usr/local/lib/python3.6/site-packages/urllib3/connection.py", line 141, in _new_conn
    (self.host, self.port), self.timeout, **extra_kw)
  File "/usr/local/lib/python3.6/site-packages/urllib3/util/connection.py", line 83, in create_connection
    raise err
  File "/usr/local/lib/python3.6/site-packages/urllib3/util/connection.py", line 73, in create_connection
    sock.connect(sa)
ConnectionRefusedError: [Errno 61] Connection refused

During handling of the above exception, another exception occurred:

Traceback (most recent call last):
  File "/usr/local/lib/python3.6/site-packages/urllib3/connectionpool.py", line 601, in urlopen
    chunked=chunked)
  File "/usr/local/lib/python3.6/site-packages/urllib3/connectionpool.py", line 357, in _make_request
    conn.request(method, url, **httplib_request_kw)
  File "/usr/local/Cellar/python3/3.6.2/Frameworks/Python.framework/Versions/3.6/lib/python3.6/http/client.py", line 1239, in request
    self._send_request(method, url, body, headers, encode_chunked)
  File "/usr/local/Cellar/python3/3.6.2/Frameworks/Python.framework/Versions/3.6/lib/python3.6/http/client.py", line 1285, in _send_request
    self.endheaders(body, encode_chunked=encode_chunked)
  File "/usr/local/Cellar/python3/3.6.2/Frameworks/Python.framework/Versions/3.6/lib/python3.6/http/client.py", line 1234, in endheaders
    self._send_output(message_body, encode_chunked=encode_chunked)
  File "/usr/local/Cellar/python3/3.6.2/Frameworks/Python.framework/Versions/3.6/lib/python3.6/http/client.py", line 1026, in _send_output
    self.send(msg)
  File "/usr/local/Cellar/python3/3.6.2/Frameworks/Python.framework/Versions/3.6/lib/python3.6/http/client.py", line 964, in send
    self.connect()
  File "/usr/local/lib/python3.6/site-packages/urllib3/connection.py", line 166, in connect
    conn = self._new_conn()
  File "/usr/local/lib/python3.6/site-packages/urllib3/connection.py", line 150, in _new_conn
    self, "Failed to establish a new connection: %s" % e)
urllib3.exceptions.NewConnectionError: <urllib3.connection.HTTPConnection object at 0x105662240>: Failed to establish a new connection: [Errno 61] Connection refused

During handling of the above exception, another exception occurred:

Traceback (most recent call last):
  File "/usr/local/lib/python3.6/site-packages/requests/adapters.py", line 440, in send
    timeout=timeout
  File "/usr/local/lib/python3.6/site-packages/urllib3/connectionpool.py", line 639, in urlopen
    _stacktrace=sys.exc_info()[2])
  File "/usr/local/lib/python3.6/site-packages/urllib3/util/retry.py", line 388, in increment
    raise MaxRetryError(_pool, url, error or ResponseError(cause))
urllib3.exceptions.MaxRetryError: HTTPConnectionPool(host='localhost', port=4200): Max retries exceeded with url: /get-blockchain (Caused by NewConnectionError('<urllib3.connection.HTTPConnection object at 0x105662240>: Failed to establish a new connection: [Errno 61] Connection refused',))

During handling of the above exception, another exception occurred:

Traceback (most recent call last):
  File "/usr/local/lib/python3.6/site-packages/engineio/server.py", line 405, in _trigger_event
    return self.handlers[event](*args)
  File "/usr/local/lib/python3.6/site-packages/socketio/server.py", line 522, in _handle_eio_message
    self._handle_event(sid, pkt.namespace, pkt.id, pkt.data)
  File "/usr/local/lib/python3.6/site-packages/socketio/server.py", line 458, in _handle_event
    self._handle_event_internal(self, sid, data, namespace, id)
  File "/usr/local/lib/python3.6/site-packages/socketio/server.py", line 461, in _handle_event_internal
    r = server._trigger_event(data[0], namespace, sid, *data[1:])
  File "/usr/local/lib/python3.6/site-packages/socketio/server.py", line 490, in _trigger_event
    return self.handlers[namespace][event](*args)
  File "/usr/local/lib/python3.6/site-packages/flask_socketio/__init__.py", line 243, in _handler
    *args)
  File "/usr/local/lib/python3.6/site-packages/flask_socketio/__init__.py", line 626, in _handle_event
    ret = handler(*args)
  File "/Users/siddharthsudheer/repos/computer-science/alysida/webapp/app/routes/index.py", line 32, in get_event
    resp = requests.get(endpoint)
  File "/usr/local/lib/python3.6/site-packages/requests/api.py", line 72, in get
    return request('get', url, params=params, **kwargs)
  File "/usr/local/lib/python3.6/site-packages/requests/api.py", line 58, in request
    return session.request(method=method, url=url, **kwargs)
  File "/usr/local/lib/python3.6/site-packages/requests/sessions.py", line 508, in request
    resp = self.send(prep, **send_kwargs)
  File "/usr/local/lib/python3.6/site-packages/requests/sessions.py", line 618, in send
    r = adapter.send(request, **kwargs)
  File "/usr/local/lib/python3.6/site-packages/requests/adapters.py", line 508, in send
    raise ConnectionError(e, request=request)
requests.exceptions.ConnectionError: HTTPConnectionPool(host='localhost', port=4200): Max retries exceeded with url: /get-blockchain (Caused by NewConnectionError('<urllib3.connection.HTTPConnection object at 0x105662240>: Failed to establish a new connection: [Errno 61] Connection refused',))
127.0.0.1 - - [12/Dec/2017 22:15:00] "GET /socket.io/?EIO=3&transport=websocket&sid=9dd38cb89b184394b26bf585c6630e57 HTTP/1.1" 200 0 698.115943
(8357) accepted ('127.0.0.1', 51589)
127.0.0.1 - - [12/Dec/2017 22:15:00] "GET / HTTP/1.1" 304 266 0.001482
127.0.0.1 - - [12/Dec/2017 22:15:00] "GET /lib/jquery-ui/themes/smoothness/jquery-ui.css HTTP/1.1" 304 262 0.001933
127.0.0.1 - - [12/Dec/2017 22:15:00] "GET /pages/mainPage/css/app.css HTTP/1.1" 304 268 0.001673
127.0.0.1 - - [12/Dec/2017 22:15:00] "GET /lib/jquery/dist/jquery.js HTTP/1.1" 304 263 0.001247
127.0.0.1 - - [12/Dec/2017 22:15:00] "GET /lib/jquery-ui/jquery-ui.js HTTP/1.1" 304 263 0.001192
127.0.0.1 - - [12/Dec/2017 22:15:00] "GET /lib/lodash/dist/lodash.js HTTP/1.1" 304 263 0.001606
127.0.0.1 - - [12/Dec/2017 22:15:00] "GET /lib/angular/angular.js HTTP/1.1" 304 264 0.003368
127.0.0.1 - - [12/Dec/2017 22:15:00] "GET /lib/angular-resource/angular-resource.js HTTP/1.1" 304 262 0.001285
127.0.0.1 - - [12/Dec/2017 22:15:00] "GET /lib/angular-route/angular-route.js HTTP/1.1" 304 262 0.001359
127.0.0.1 - - [12/Dec/2017 22:15:00] "GET /lib/angular-ui-date/dist/date.js HTTP/1.1" 304 261 0.001194
127.0.0.1 - - [12/Dec/2017 22:15:00] "GET /lib/angular-animate/angular-animate.js HTTP/1.1" 304 263 0.003917
127.0.0.1 - - [12/Dec/2017 22:15:00] "GET /pages/mainPage/js/app.js HTTP/1.1" 304 266 0.002890
(8357) accepted ('127.0.0.1', 51590)
(8357) accepted ('127.0.0.1', 51591)
(8357) accepted ('127.0.0.1', 51592)
(8357) accepted ('127.0.0.1', 51593)
(8357) accepted ('127.0.0.1', 51594)
127.0.0.1 - - [12/Dec/2017 22:15:01] "GET /socket.io/?EIO=3&transport=polling&t=M1DtaSD HTTP/1.1" 200 381 0.000583
127.0.0.1 - - [12/Dec/2017 22:15:01] "POST /socket.io/?EIO=3&transport=polling&t=M1DtaTq&sid=727e528a42be494e989c87d3264cd995 HTTP/1.1" 200 199 0.001151
127.0.0.1 - - [12/Dec/2017 22:15:01] "GET /socket.io/?EIO=3&transport=polling&t=M1DtaTx&sid=727e528a42be494e989c87d3264cd995 HTTP/1.1" 200 270 0.000275
(8357) accepted ('127.0.0.1', 51597)
message handler error
Traceback (most recent call last):
  File "/usr/local/lib/python3.6/site-packages/urllib3/connection.py", line 141, in _new_conn
    (self.host, self.port), self.timeout, **extra_kw)
  File "/usr/local/lib/python3.6/site-packages/urllib3/util/connection.py", line 83, in create_connection
    raise err
  File "/usr/local/lib/python3.6/site-packages/urllib3/util/connection.py", line 73, in create_connection
    sock.connect(sa)
ConnectionRefusedError: [Errno 61] Connection refused

During handling of the above exception, another exception occurred:

Traceback (most recent call last):
  File "/usr/local/lib/python3.6/site-packages/urllib3/connectionpool.py", line 601, in urlopen
    chunked=chunked)
  File "/usr/local/lib/python3.6/site-packages/urllib3/connectionpool.py", line 357, in _make_request
    conn.request(method, url, **httplib_request_kw)
  File "/usr/local/Cellar/python3/3.6.2/Frameworks/Python.framework/Versions/3.6/lib/python3.6/http/client.py", line 1239, in request
    self._send_request(method, url, body, headers, encode_chunked)
  File "/usr/local/Cellar/python3/3.6.2/Frameworks/Python.framework/Versions/3.6/lib/python3.6/http/client.py", line 1285, in _send_request
    self.endheaders(body, encode_chunked=encode_chunked)
  File "/usr/local/Cellar/python3/3.6.2/Frameworks/Python.framework/Versions/3.6/lib/python3.6/http/client.py", line 1234, in endheaders
    self._send_output(message_body, encode_chunked=encode_chunked)
  File "/usr/local/Cellar/python3/3.6.2/Frameworks/Python.framework/Versions/3.6/lib/python3.6/http/client.py", line 1026, in _send_output
    self.send(msg)
  File "/usr/local/Cellar/python3/3.6.2/Frameworks/Python.framework/Versions/3.6/lib/python3.6/http/client.py", line 964, in send
    self.connect()
  File "/usr/local/lib/python3.6/site-packages/urllib3/connection.py", line 166, in connect
    conn = self._new_conn()
  File "/usr/local/lib/python3.6/site-packages/urllib3/connection.py", line 150, in _new_conn
    self, "Failed to establish a new connection: %s" % e)
urllib3.exceptions.NewConnectionError: <urllib3.connection.HTTPConnection object at 0x105662eb8>: Failed to establish a new connection: [Errno 61] Connection refused

During handling of the above exception, another exception occurred:

Traceback (most recent call last):
  File "/usr/local/lib/python3.6/site-packages/requests/adapters.py", line 440, in send
    timeout=timeout
  File "/usr/local/lib/python3.6/site-packages/urllib3/connectionpool.py", line 639, in urlopen
    _stacktrace=sys.exc_info()[2])
  File "/usr/local/lib/python3.6/site-packages/urllib3/util/retry.py", line 388, in increment
    raise MaxRetryError(_pool, url, error or ResponseError(cause))
urllib3.exceptions.MaxRetryError: HTTPConnectionPool(host='localhost', port=4200): Max retries exceeded with url: /get-peer-addresses (Caused by NewConnectionError('<urllib3.connection.HTTPConnection object at 0x105662eb8>: Failed to establish a new connection: [Errno 61] Connection refused',))

During handling of the above exception, another exception occurred:

Traceback (most recent call last):
  File "/usr/local/lib/python3.6/site-packages/engineio/server.py", line 405, in _trigger_event
    return self.handlers[event](*args)
  File "/usr/local/lib/python3.6/site-packages/socketio/server.py", line 522, in _handle_eio_message
    self._handle_event(sid, pkt.namespace, pkt.id, pkt.data)
  File "/usr/local/lib/python3.6/site-packages/socketio/server.py", line 458, in _handle_event
    self._handle_event_internal(self, sid, data, namespace, id)
  File "/usr/local/lib/python3.6/site-packages/socketio/server.py", line 461, in _handle_event_internal
    r = server._trigger_event(data[0], namespace, sid, *data[1:])
  File "/usr/local/lib/python3.6/site-packages/socketio/server.py", line 490, in _trigger_event
    return self.handlers[namespace][event](*args)
  File "/usr/local/lib/python3.6/site-packages/flask_socketio/__init__.py", line 243, in _handler
    *args)
  File "/usr/local/lib/python3.6/site-packages/flask_socketio/__init__.py", line 626, in _handle_event
    ret = handler(*args)
  File "/Users/siddharthsudheer/repos/computer-science/alysida/webapp/app/routes/index.py", line 52, in get_peers
    resp = requests.get(endpoint)
  File "/usr/local/lib/python3.6/site-packages/requests/api.py", line 72, in get
    return request('get', url, params=params, **kwargs)
  File "/usr/local/lib/python3.6/site-packages/requests/api.py", line 58, in request
    return session.request(method=method, url=url, **kwargs)
  File "/usr/local/lib/python3.6/site-packages/requests/sessions.py", line 508, in request
    resp = self.send(prep, **send_kwargs)
  File "/usr/local/lib/python3.6/site-packages/requests/sessions.py", line 618, in send
    r = adapter.send(request, **kwargs)
  File "/usr/local/lib/python3.6/site-packages/requests/adapters.py", line 508, in send
    raise ConnectionError(e, request=request)
requests.exceptions.ConnectionError: HTTPConnectionPool(host='localhost', port=4200): Max retries exceeded with url: /get-peer-addresses (Caused by NewConnectionError('<urllib3.connection.HTTPConnection object at 0x105662eb8>: Failed to establish a new connection: [Errno 61] Connection refused',))
127.0.0.1 - - [12/Dec/2017 22:15:01] "POST /socket.io/?EIO=3&transport=polling&t=M1DtaUU&sid=727e528a42be494e989c87d3264cd995 HTTP/1.1" 200 199 0.009676
127.0.0.1 - - [12/Dec/2017 22:15:01] "GET /socket.io/?EIO=3&transport=polling&t=M1DtaUV&sid=727e528a42be494e989c87d3264cd995 HTTP/1.1" 200 215 0.000289
message handler error
Traceback (most recent call last):
  File "/usr/local/lib/python3.6/site-packages/urllib3/connection.py", line 141, in _new_conn
    (self.host, self.port), self.timeout, **extra_kw)
  File "/usr/local/lib/python3.6/site-packages/urllib3/util/connection.py", line 83, in create_connection
    raise err
  File "/usr/local/lib/python3.6/site-packages/urllib3/util/connection.py", line 73, in create_connection
    sock.connect(sa)
ConnectionRefusedError: [Errno 61] Connection refused

During handling of the above exception, another exception occurred:

Traceback (most recent call last):
  File "/usr/local/lib/python3.6/site-packages/urllib3/connectionpool.py", line 601, in urlopen
    chunked=chunked)
  File "/usr/local/lib/python3.6/site-packages/urllib3/connectionpool.py", line 357, in _make_request
    conn.request(method, url, **httplib_request_kw)
  File "/usr/local/Cellar/python3/3.6.2/Frameworks/Python.framework/Versions/3.6/lib/python3.6/http/client.py", line 1239, in request
    self._send_request(method, url, body, headers, encode_chunked)
  File "/usr/local/Cellar/python3/3.6.2/Frameworks/Python.framework/Versions/3.6/lib/python3.6/http/client.py", line 1285, in _send_request
    self.endheaders(body, encode_chunked=encode_chunked)
  File "/usr/local/Cellar/python3/3.6.2/Frameworks/Python.framework/Versions/3.6/lib/python3.6/http/client.py", line 1234, in endheaders
    self._send_output(message_body, encode_chunked=encode_chunked)
  File "/usr/local/Cellar/python3/3.6.2/Frameworks/Python.framework/Versions/3.6/lib/python3.6/http/client.py", line 1026, in _send_output
    self.send(msg)
  File "/usr/local/Cellar/python3/3.6.2/Frameworks/Python.framework/Versions/3.6/lib/python3.6/http/client.py", line 964, in send
    self.connect()
  File "/usr/local/lib/python3.6/site-packages/urllib3/connection.py", line 166, in connect
    conn = self._new_conn()
  File "/usr/local/lib/python3.6/site-packages/urllib3/connection.py", line 150, in _new_conn
    self, "Failed to establish a new connection: %s" % e)
urllib3.exceptions.NewConnectionError: <urllib3.connection.HTTPConnection object at 0x10494a588>: Failed to establish a new connection: [Errno 61] Connection refused

During handling of the above exception, another exception occurred:

Traceback (most recent call last):
  File "/usr/local/lib/python3.6/site-packages/requests/adapters.py", line 440, in send
    timeout=timeout
  File "/usr/local/lib/python3.6/site-packages/urllib3/connectionpool.py", line 639, in urlopen
    _stacktrace=sys.exc_info()[2])
  File "/usr/local/lib/python3.6/site-packages/urllib3/util/retry.py", line 388, in increment
    raise MaxRetryError(_pool, url, error or ResponseError(cause))
urllib3.exceptions.MaxRetryError: HTTPConnectionPool(host='localhost', port=4200): Max retries exceeded with url: /get-blockchain (Caused by NewConnectionError('<urllib3.connection.HTTPConnection object at 0x10494a588>: Failed to establish a new connection: [Errno 61] Connection refused',))

During handling of the above exception, another exception occurred:

Traceback (most recent call last):
  File "/usr/local/lib/python3.6/site-packages/engineio/server.py", line 405, in _trigger_event
    return self.handlers[event](*args)
  File "/usr/local/lib/python3.6/site-packages/socketio/server.py", line 522, in _handle_eio_message
    self._handle_event(sid, pkt.namespace, pkt.id, pkt.data)
  File "/usr/local/lib/python3.6/site-packages/socketio/server.py", line 458, in _handle_event
    self._handle_event_internal(self, sid, data, namespace, id)
  File "/usr/local/lib/python3.6/site-packages/socketio/server.py", line 461, in _handle_event_internal
    r = server._trigger_event(data[0], namespace, sid, *data[1:])
  File "/usr/local/lib/python3.6/site-packages/socketio/server.py", line 490, in _trigger_event
    return self.handlers[namespace][event](*args)
  File "/usr/local/lib/python3.6/site-packages/flask_socketio/__init__.py", line 243, in _handler
    *args)
  File "/usr/local/lib/python3.6/site-packages/flask_socketio/__init__.py", line 626, in _handle_event
    ret = handler(*args)
  File "/Users/siddharthsudheer/repos/computer-science/alysida/webapp/app/routes/index.py", line 32, in get_event
    resp = requests.get(endpoint)
  File "/usr/local/lib/python3.6/site-packages/requests/api.py", line 72, in get
    return request('get', url, params=params, **kwargs)
  File "/usr/local/lib/python3.6/site-packages/requests/api.py", line 58, in request
    return session.request(method=method, url=url, **kwargs)
  File "/usr/local/lib/python3.6/site-packages/requests/sessions.py", line 508, in request
    resp = self.send(prep, **send_kwargs)
  File "/usr/local/lib/python3.6/site-packages/requests/sessions.py", line 618, in send
    r = adapter.send(request, **kwargs)
  File "/usr/local/lib/python3.6/site-packages/requests/adapters.py", line 508, in send
    raise ConnectionError(e, request=request)
requests.exceptions.ConnectionError: HTTPConnectionPool(host='localhost', port=4200): Max retries exceeded with url: /get-blockchain (Caused by NewConnectionError('<urllib3.connection.HTTPConnection object at 0x10494a588>: Failed to establish a new connection: [Errno 61] Connection refused',))
